[0m01:20:10.647795 [debug] [MainThread]: Sending event: {'category': 'dbt', 'action': 'invocation', 'label': 'start', 'context': [<snowplow_tracker.self_describing_json.SelfDescribingJson object at 0x768e35057b00>, <snowplow_tracker.self_describing_json.SelfDescribingJson object at 0x768e34a6d910>, <snowplow_tracker.self_describing_json.SelfDescribingJson object at 0x768e34a6f080>]}


============================== 01:20:10.653202 | 5212524f-9fd1-4129-b3a0-2114ed9e9d2b ==============================
[0m01:20:10.653202 [info ] [MainThread]: Running with dbt=1.9.2
[0m01:20:10.654009 [debug] [MainThread]: running dbt with arguments {'printer_width': '80', 'indirect_selection': 'eager', 'write_json': 'True', 'log_cache_events': 'False', 'partial_parse': 'True', 'cache_selected_only': 'False', 'warn_error': 'None', 'debug': 'False', 'fail_fast': 'False', 'log_path': 'logs', 'profiles_dir': '/home/codespace/.dbt', 'version_check': 'True', 'use_colors': 'True', 'use_experimental_parser': 'False', 'empty': 'None', 'quiet': 'False', 'no_print': 'None', 'warn_error_options': 'WarnErrorOptions(include=[], exclude=[])', 'invocation_command': 'dbt docs generate', 'static_parser': 'True', 'introspect': 'True', 'target_path': 'None', 'log_format': 'default', 'send_anonymous_usage_stats': 'True'}
[0m01:20:10.654645 [error] [MainThread]: Encountered an error:
Runtime Error
  No dbt_project.yml found at expected path /workspaces/snow_dbt_airbnb/dbt_project.yml
  Verify that each entry within packages.yml (and their transitive dependencies) contains a file named dbt_project.yml
  
[0m01:20:10.656939 [debug] [MainThread]: Resource report: {"command_name": "generate", "command_success": false, "command_wall_clock_time": 0.21881305, "process_in_blocks": "79336", "process_kernel_time": 0.338979, "process_mem_max_rss": "87988", "process_out_blocks": "8", "process_user_time": 1.645909}
[0m01:20:10.657863 [debug] [MainThread]: Command `dbt docs generate` failed at 01:20:10.657712 after 0.22 seconds
[0m01:20:10.658638 [debug] [MainThread]: Sending event: {'category': 'dbt', 'action': 'invocation', 'label': 'end', 'context': [<snowplow_tracker.self_describing_json.SelfDescribingJson object at 0x768e355bb080>, <snowplow_tracker.self_describing_json.SelfDescribingJson object at 0x768e34d81700>, <snowplow_tracker.self_describing_json.SelfDescribingJson object at 0x768e34e8bd40>]}
[0m01:20:10.659476 [debug] [MainThread]: Flushing usage events
[0m01:20:11.020799 [debug] [MainThread]: An error was encountered while trying to flush usage events
[0m01:21:45.318789 [debug] [MainThread]: Sending event: {'category': 'dbt', 'action': 'invocation', 'label': 'start', 'context': [<snowplow_tracker.self_describing_json.SelfDescribingJson object at 0x7380f024da30>, <snowplow_tracker.self_describing_json.SelfDescribingJson object at 0x7380f024d700>, <snowplow_tracker.self_describing_json.SelfDescribingJson object at 0x7380f024dca0>]}


============================== 01:21:45.322088 | c919c05a-f082-421f-890b-23896ae01aa2 ==============================
[0m01:21:45.322088 [info ] [MainThread]: Running with dbt=1.9.2
[0m01:21:45.322978 [debug] [MainThread]: running dbt with arguments {'printer_width': '80', 'indirect_selection': 'eager', 'write_json': 'True', 'log_cache_events': 'False', 'partial_parse': 'True', 'cache_selected_only': 'False', 'profiles_dir': '/home/codespace/.dbt', 'version_check': 'True', 'warn_error': 'None', 'log_path': 'logs', 'fail_fast': 'False', 'debug': 'False', 'use_colors': 'True', 'use_experimental_parser': 'False', 'no_print': 'None', 'quiet': 'False', 'empty': 'None', 'warn_error_options': 'WarnErrorOptions(include=[], exclude=[])', 'introspect': 'True', 'invocation_command': 'dbt docs generate', 'static_parser': 'True', 'target_path': 'None', 'log_format': 'default', 'send_anonymous_usage_stats': 'True'}
[0m01:21:45.323567 [error] [MainThread]: Encountered an error:
Runtime Error
  No dbt_project.yml found at expected path /workspaces/snow_dbt_airbnb/dbt_project.yml
  Verify that each entry within packages.yml (and their transitive dependencies) contains a file named dbt_project.yml
  
[0m01:21:45.324650 [debug] [MainThread]: Resource report: {"command_name": "generate", "command_success": false, "command_wall_clock_time": 0.075707234, "process_in_blocks": "0", "process_kernel_time": 0.135213, "process_mem_max_rss": "88236", "process_out_blocks": "16", "process_user_time": 1.319328}
[0m01:21:45.325250 [debug] [MainThread]: Command `dbt docs generate` failed at 01:21:45.325140 after 0.08 seconds
[0m01:21:45.325712 [debug] [MainThread]: Sending event: {'category': 'dbt', 'action': 'invocation', 'label': 'end', 'context': [<snowplow_tracker.self_describing_json.SelfDescribingJson object at 0x7380f39ffb30>, <snowplow_tracker.self_describing_json.SelfDescribingJson object at 0x7380f39ffb60>, <snowplow_tracker.self_describing_json.SelfDescribingJson object at 0x7380f024dd00>]}
[0m01:21:45.326240 [debug] [MainThread]: Flushing usage events
[0m01:21:45.698487 [debug] [MainThread]: An error was encountered while trying to flush usage events
